<?xml version="1.0"?>
<robot xmlns:xacro="http://www.ros.org/xacro" name="head">
  <link name="base_link"/>

  <link name="head_link"/>

  <joint name="head_pan_joint" type="revolute">
    <parent link="base_link"/>
    <child link="head_link"/>
    <origin xyz="0 0 0" rpy="0 0 0"/>
    <axis xyz="0 0 1"/>
    <limit lower="-1.57" upper="1.57" velocity="1.0" effort="100"/>
  </joint>

  <transmission name="head_pan_transmission">
    <type>transmission_interface/SimpleTransmission</type>
    <joint name="head_pan_joint">
      <hardwareInterface>PositionJointInterface</hardwareInterface>
    </joint>
    <actuator name="head_pan_motor">
      <hardwareInterface>PositionJointInterface</hardwareInterface>
    </actuator>
  </transmission>

  <ros2_control name="dynamixel_hardware_interface" type="system">
    <hardware>
      <plugin>dynamixel_hardware/DynamixelHardware</plugin>
      <param name="usb_port">/dev/ttyUSB0</param>
      <param name="baud_rate">1000000</param>
      <param name="extended_mode">true</param>
    </hardware>
    <joint name="head_pan_joint">
      <command_interface name="position">
        <param name="min">-3.14</param>
        <param name="max">3.14</param>
      </command_interface>
      <command_interface name="velocity"/>
      <state_interface name="position"/>
      <state_interface name="velocity"/>
      <state_interface name="effort"/>
      <param name="id">1</param>
    </joint>
  </ros2_control>
</robot>
